<?xml version="1.0" encoding="utf-8"?>
<robot name="partnet_2627c3acbf2993d7f9651db54962898">
 <link name="base"/>
 <link name="link_0">
  <visual>
   <geometry>
    <mesh filename="cvx_processed/link_0_visual.obj"/>
   </geometry>
  </visual>
  <collision>
   <geometry>
    <mesh filename="cvx_processed/original-4_cvx0.obj"/>
   </geometry>
  </collision>
  <collision>
   <geometry>
    <mesh filename="cvx_processed/original-3_cvx0.obj"/>
   </geometry>
  </collision>
  <collision>
   <geometry>
    <mesh filename="cvx_processed/original-3_cvx1.obj"/>
   </geometry>
  </collision>
  <collision>
   <geometry>
    <mesh filename="cvx_processed/original-3_cvx2.obj"/>
   </geometry>
  </collision>
  <collision>
   <geometry>
    <mesh filename="cvx_processed/original-3_cvx3.obj"/>
   </geometry>
  </collision>
  <collision>
   <geometry>
    <mesh filename="cvx_processed/original-3_cvx4.obj"/>
   </geometry>
  </collision>
  <collision>
   <geometry>
    <mesh filename="cvx_processed/original-3_cvx5.obj"/>
   </geometry>
  </collision>
  <collision>
   <geometry>
    <mesh filename="cvx_processed/original-3_cvx6.obj"/>
   </geometry>
  </collision>
  <collision>
   <geometry>
    <mesh filename="cvx_processed/original-3_cvx7.obj"/>
   </geometry>
  </collision>
  <collision>
   <geometry>
    <mesh filename="cvx_processed/original-3_cvx8.obj"/>
   </geometry>
  </collision>
  <collision>
   <geometry>
    <mesh filename="cvx_processed/original-3_cvx9.obj"/>
   </geometry>
  </collision>
  <collision>
   <geometry>
    <mesh filename="cvx_processed/original-2_cvx0.obj"/>
   </geometry>
  </collision>
  <collision>
   <geometry>
    <mesh filename="cvx_processed/original-2_cvx1.obj"/>
   </geometry>
  </collision>
  <collision>
   <geometry>
    <mesh filename="cvx_processed/original-2_cvx2.obj"/>
   </geometry>
  </collision>
  <collision>
   <geometry>
    <mesh filename="cvx_processed/original-2_cvx3.obj"/>
   </geometry>
  </collision>
  <collision>
   <geometry>
    <mesh filename="cvx_processed/original-2_cvx4.obj"/>
   </geometry>
  </collision>
  <collision>
   <geometry>
    <mesh filename="cvx_processed/original-2_cvx5.obj"/>
   </geometry>
  </collision>
  <collision>
   <geometry>
    <mesh filename="cvx_processed/original-2_cvx6.obj"/>
   </geometry>
  </collision>
  <collision>
   <geometry>
    <mesh filename="cvx_processed/original-2_cvx7.obj"/>
   </geometry>
  </collision>
  <collision>
   <geometry>
    <mesh filename="cvx_processed/original-2_cvx8.obj"/>
   </geometry>
  </collision>
  <collision>
   <geometry>
    <mesh filename="cvx_processed/original-2_cvx9.obj"/>
   </geometry>
  </collision>
 </link>
 <joint name="joint_0" type="revolute">
  <origin xyz="0 0.6878317663455735 -0.000856264051981295"/>
  <axis xyz="-1 0 0"/>
  <child link="link_0"/>
  <parent link="link_1"/>
  <limit lower="-0.0" upper="4.624424386084175"/>
 </joint>
 <link name="link_1">
  <visual>
   <geometry>
    <mesh filename="cvx_processed/link_1_visual.obj"/>
   </geometry>
  </visual>
  <collision>
   <geometry>
    <mesh filename="cvx_processed/original-5_cvx0.obj"/>
   </geometry>
  </collision>
  <collision>
   <geometry>
    <mesh filename="cvx_processed/original-5_cvx1.obj"/>
   </geometry>
  </collision>
  <collision>
   <geometry>
    <mesh filename="cvx_processed/original-5_cvx2.obj"/>
   </geometry>
  </collision>
  <collision>
   <geometry>
    <mesh filename="cvx_processed/original-5_cvx3.obj"/>
   </geometry>
  </collision>
  <collision>
   <geometry>
    <mesh filename="cvx_processed/original-5_cvx4.obj"/>
   </geometry>
  </collision>
  <collision>
   <geometry>
    <mesh filename="cvx_processed/original-5_cvx5.obj"/>
   </geometry>
  </collision>
  <collision>
   <geometry>
    <mesh filename="cvx_processed/original-5_cvx6.obj"/>
   </geometry>
  </collision>
  <collision>
   <geometry>
    <mesh filename="cvx_processed/original-5_cvx7.obj"/>
   </geometry>
  </collision>
  <collision>
   <geometry>
    <mesh filename="cvx_processed/original-5_cvx8.obj"/>
   </geometry>
  </collision>
  <collision>
   <geometry>
    <mesh filename="cvx_processed/original-5_cvx9.obj"/>
   </geometry>
  </collision>
 </link>
 <joint name="joint_1" type="fixed">
  <origin rpy="1.570796326794897 0 -1.570796326794897" xyz="0 0 0"/>
  <child link="link_1"/>
  <parent link="base"/>
 </joint>
</robot>